#VRML_SIM R2019a utf8
WorldInfo {
}
Viewpoint {
  orientation -0.22363142754577905 -0.9489083566649609 -0.22262505534022997 1.645721848274122
  position -2.5110990057990454 1.401987128555823 0.5067197584221304
}
TexturedBackground {
}
TexturedBackgroundLight {
}
Floor {
}
Group {
  children [
    Group {
      children [
        Solid {
          translation 0 0.294 0
          rotation 0.7071067811865475 0 0.7071067811865475 0.26180030610042526
          children [
            DEF Poste1 Shape {
              appearance DEF color_post1 PBRAppearance {
                baseColor 0.7568627450980392 0.49019607843137253 0.06666666666666667
                roughness 1
                metalness 0
              }
              geometry Cylinder {
                height 0.6
                radius 0.019999999999999997
              }
            }
          ]
        }
        Transform {
          translation -0.30000000000000004 0.294 0
          rotation 0.7071067811865475 0 -0.7071067811865475 0.2618
          children [
            USE Poste1
          ]
        }
        Transform {
          translation -0.30000000000000004 0.294 0.3
          rotation -0.7071067811865476 0 -0.7071067811865476 0.2618
          children [
            USE Poste1
          ]
        }
        Transform {
          translation 0 0.294 0.30000000000000004
          rotation -0.7071067811865476 0 0.7071067811865476 0.2618
          children [
            USE Poste1
          ]
        }
        Transform {
          translation -0.15000000000000002 0.30000000000000004 0
          rotation 0 0 1 1.5707996938995747
          children [
            Shape {
              appearance USE color_post1
              geometry Cylinder {
                height 0.30000000000000004
                radius 0.019999999999999997
              }
            }
          ]
        }
        Transform {
          translation -0.15000000000000002 0.30000000000000004 0.30000000000000004
          rotation 0 0 1 1.5707996938995747
          children [
            Shape {
              appearance USE color_post1
              geometry Cylinder {
                height 0.30000000000000004
                radius 0.019999999999999997
              }
            }
          ]
        }
        Transform {
          translation -0.005 0.30000000000000004 0.16
          rotation 1 0 0 1.5707996938995747
          children [
            Shape {
              appearance USE color_post1
              geometry Cylinder {
                height 0.30000000000000004
                radius 0.019999999999999997
              }
            }
          ]
        }
        Transform {
          translation -0.3 0.30000000000000004 0.16
          rotation 1 0 0 1.5707996938995747
          children [
            Shape {
              appearance USE color_post1
              geometry Cylinder {
                height 0.30000000000000004
                radius 0.019999999999999997
              }
            }
          ]
        }
        Transform {
          translation -0.15 0.6 0.15
          children [
            Shape {
              appearance USE color_post1
              geometry Box {
                size 0.4 0.019999999999999997 0.4
              }
            }
          ]
        }
      ]
    }
    Group {
      children [
        Transform {
          translation -0.15000000000000002 0.66 0.31
          children [
            Shape {
              appearance DEF Cilindro_superior PBRAppearance {
                baseColor 0.3333333333333333 0.3411764705882353 0.3254901960784314
                roughness 1
                metalness 0
              }
              geometry Cylinder {
                height 0.1
                radius 0.019999999999999997
              }
            }
            Solid {
              translation 0.012990000000000002 0.08 0.01566679999999998
              rotation 1 -5.896672983991331e-17 5.345030677264321e-17 -1.5707996938995745
              children [
                Shape {
                  appearance DEF color PBRAppearance {
                    baseColor 0.9882352941176471 0.9137254901960784 0.30980392156862746
                    roughness 1
                    metalness 0
                  }
                  geometry Cylinder {
                    height 0.1
                    radius 0.03
                  }
                }
                HingeJoint {
                  jointParameters HingeJointParameters {
                    position -0.037566630946562214
                    axis 0 0 1
                    anchor 0 0.03 0.060000000000000005
                    minStop -0.785
                    maxStop 0.785
                  }
                  endPoint Solid {
                    translation 0.005255795178676178 0.1799226657218947 -0.00017468055622951034
                    rotation 0.017873762889938572 0.9996802262270801 -0.017887814028781496 1.5711198264257418
                    children [
                      Shape {
                        appearance USE Cilindro_superior
                        geometry Cylinder {
                          height 0.30000000000000004
                          radius 0.01
                        }
                      }
                      Solid {
                        translation 0 0.14 0
                        children [
                          Shape {
                            appearance USE color
                            geometry Box {
                              size 0.03 0.060000000000000005 0.019999999999999997
                            }
                          }
                        ]
                      }
                    ]
                    physics Physics {
                    }
                    linearVelocity 0.01076685321724216 1.2299260561130125e-09 0.00036527752947577215
                    angularVelocity -1.2651593134191203e-16 -0.07181241659207936 2.417996417684665e-07
                  }
                }
                HingeJoint {
                  jointParameters HingeJointParameters {
                    position 105.55807877441254
                    axis 0 1 0
                    anchor 0 -0.07 0
                  }
                  endPoint Solid {
                    translation 0.00026838525752346626 -0.06999999904963838 -8.737151582525256e-05
                    rotation -0.6559971262736747 -0.5336974106128242 0.5336992076308968 4.302748725806354
                    children [
                      Transform {
                        children [
                          Solid {
                            children [
                              DEF elize Shape {
                                appearance USE Cilindro_superior
                                geometry Cylinder {
                                  height 0.6
                                  radius 0.019999999999999997
                                }
                              }
                              Solid {
                                translation 0 -0.27 0.02
                                children [
                                  DEF caja_elize Shape {
                                    appearance USE color
                                    geometry Box {
                                      size 0.06999999999999999 0.13 0.01
                                    }
                                  }
                                ]
                              }
                              Transform {
                                translation 0 0.27 0.02
                                children [
                                  USE caja_elize
                                ]
                              }
                            ]
                            physics Physics {
                            }
                          }
                          Solid {
                            rotation 0 0 1 1.5707963220000003
                            children [
                              DEF elize Shape {
                                appearance USE Cilindro_superior
                                geometry Cylinder {
                                  height 0.6
                                  radius 0.019999999999999997
                                }
                              }
                              Solid {
                                translation 0 -0.27 0.02
                                children [
                                  DEF caja_elize Shape {
                                    appearance USE color
                                    geometry Box {
                                      size 0.06999999999999999 0.13 0.01
                                    }
                                  }
                                ]
                              }
                              Transform {
                                translation 0 0.27 0.02
                                children [
                                  USE caja_elize
                                ]
                              }
                            ]
                            name "solid(1)"
                            physics Physics {
                            }
                          }
                          Solid {
                            rotation 0 0 1 5.497787127
                            children [
                              DEF elize Shape {
                                appearance USE Cilindro_superior
                                geometry Cylinder {
                                  height 0.6
                                  radius 0.019999999999999997
                                }
                              }
                              Solid {
                                translation 0 -0.27 0.02
                                children [
                                  DEF caja_elize Shape {
                                    appearance USE color
                                    geometry Box {
                                      size 0.06999999999999999 0.13 0.01
                                    }
                                  }
                                ]
                              }
                              Transform {
                                translation 0 0.27 0.02
                                children [
                                  USE caja_elize
                                ]
                              }
                            ]
                            name "solid(2)"
                            physics Physics {
                            }
                          }
                          Solid {
                            rotation 0 0 1 3.926990805
                            children [
                              DEF elize Shape {
                                appearance USE Cilindro_superior
                                geometry Cylinder {
                                  height 0.6
                                  radius 0.019999999999999997
                                }
                              }
                              Solid {
                                translation 0 -0.27 0.02
                                children [
                                  DEF caja_elize Shape {
                                    appearance USE color
                                    geometry Box {
                                      size 0.06999999999999999 0.13 0.01
                                    }
                                  }
                                ]
                              }
                              Transform {
                                translation 0 0.27 0.02
                                children [
                                  USE caja_elize
                                ]
                              }
                            ]
                            name "solid(3)"
                            physics Physics {
                            }
                          }
                        ]
                      }
                    ]
                    name "solid(1)"
                    physics Physics {
                    }
                    linearVelocity -0.00017677818318044086 -0.000893818478492546 3.0095802499111483e-09
                    angularVelocity -3.7482956699094007e-17 -1.065599820969457e-05 -3.164736173344539
                  }
                }
              ]
              name "solid(1)"
            }
          ]
        }
      ]
    }
  ]
}
