#VRML_SIM R2019a utf8
WorldInfo {
}
Viewpoint {
  orientation 0.339280105659746 0.9172643182447697 0.2086029251436072 5.073572807652111
  position -1.6025446050453669 1.2757441562992744 1.0565185389903324
}
TexturedBackground {
}
TexturedBackgroundLight {
}
Floor {
}
Group {
  children [
    Group {
      children [
        Solid {
          translation 0 0.294 0
          rotation 0.7071067811865475 0 0.7071067811865475 0.26180030610042526
          children [
            DEF Poste1 Shape {
              appearance DEF color_post1 PBRAppearance {
                baseColor 0.7568627450980392 0.49019607843137253 0.06666666666666667
                roughness 1
                metalness 0
              }
              geometry Cylinder {
                height 0.6
                radius 0.019999999999999997
              }
            }
          ]
        }
        Transform {
          translation -0.30000000000000004 0.294 0
          rotation 0.7071067811865475 0 -0.7071067811865475 0.2618
          children [
            USE Poste1
          ]
        }
        Transform {
          translation -0.30000000000000004 0.294 0.3
          rotation -0.7071067811865476 0 -0.7071067811865476 0.2618
          children [
            USE Poste1
          ]
        }
        Transform {
          translation 0 0.294 0.30000000000000004
          rotation -0.7071067811865476 0 0.7071067811865476 0.2618
          children [
            USE Poste1
          ]
        }
        Transform {
          translation -0.15000000000000002 0.30000000000000004 0
          rotation 0 0 1 1.5707996938995747
          children [
            Shape {
              appearance USE color_post1
              geometry Cylinder {
                height 0.30000000000000004
                radius 0.019999999999999997
              }
            }
          ]
        }
        Transform {
          translation -0.15000000000000002 0.30000000000000004 0.30000000000000004
          rotation 0 0 1 1.5707996938995747
          children [
            Shape {
              appearance USE color_post1
              geometry Cylinder {
                height 0.30000000000000004
                radius 0.019999999999999997
              }
            }
          ]
        }
        Transform {
          translation -0.005 0.30000000000000004 0.16
          rotation 1 0 0 1.5707996938995747
          children [
            Shape {
              appearance USE color_post1
              geometry Cylinder {
                height 0.30000000000000004
                radius 0.019999999999999997
              }
            }
          ]
        }
        Transform {
          translation -0.3 0.30000000000000004 0.16
          rotation 1 0 0 1.5707996938995747
          children [
            Shape {
              appearance USE color_post1
              geometry Cylinder {
                height 0.30000000000000004
                radius 0.019999999999999997
              }
            }
          ]
        }
        Transform {
          translation -0.15 0.6 0.15
          children [
            Shape {
              appearance USE color_post1
              geometry Box {
                size 0.4 0.019999999999999997 0.4
              }
            }
          ]
        }
      ]
    }
    Group {
      children [
        Transform {
          translation -0.15 0.65 0.15
          children [
            Shape {
              appearance DEF Cilindro_superior PBRAppearance {
                baseColor 0.3333333333333333 0.3411764705882353 0.3254901960784314
                roughness 1
                metalness 0
              }
              geometry Cylinder {
                height 0.1
                radius 0.019999999999999997
              }
            }
            Solid {
              translation 0 0.07 0
              rotation 1 0 0 -1.5707996938995747
              children [
                Shape {
                  geometry Cylinder {
                    height 0.1
                    radius 0.03
                  }
                }
                HingeJoint {
                  jointParameters HingeJointParameters {
                    position -0.18493183890124007
                    axis 0 0 1
                    anchor 0 0.03 0.060000000000000005
                    minStop -0.785
                    maxStop 0.785
                  }
                  endPoint Solid {
                    translation 0.027475194779251436 0.17746224490303344 -1.3877787807814457e-17
                    rotation 0.09194311170786129 0.9915104564988912 -0.09194280212630093 1.5793253754273615
                    children [
                      Shape {
                        appearance USE Cilindro_superior
                        geometry Cylinder {
                          height 0.30000000000000004
                          radius 0.01
                        }
                      }
                      Solid {
                        translation 0 0.14 0
                        children [
                          Shape {
                            geometry Box {
                              size 0.03 0.060000000000000005 0.019999999999999997
                            }
                          }
                        ]
                      }
                    ]
                    physics Physics {
                    }
                    linearVelocity 0.044590508900575115 2.7221553580144698e-08 0.008084620165832355
                    angularVelocity -1.1828911338150186e-14 -0.3020499297667564 1.0170325018851272e-06
                  }
                }
              ]
              name "solid(1)"
            }
          ]
        }
      ]
    }
  ]
}
