#VRML_SIM R2019a utf8
WorldInfo {
}
Viewpoint {
  orientation 0.12044519083115972 0.9828814482349447 0.13941669455708414 4.506660302171369
  position -1.447157555402508 0.9566364505531579 0.1277282444057289
}
TexturedBackground {
}
TexturedBackgroundLight {
}
Floor {
}
Group {
  children [
    Group {
      children [
        Solid {
          translation 0 0.294 0
          rotation 0.7071067811865475 0 0.7071067811865475 0.26180030610042526
          children [
            DEF Poste1 Shape {
              appearance DEF color_post1 PBRAppearance {
                baseColor 0.7568627450980392 0.49019607843137253 0.06666666666666667
                roughness 1
                metalness 0
              }
              geometry Cylinder {
                height 0.6
                radius 0.019999999999999997
              }
            }
          ]
        }
        Transform {
          translation -0.30000000000000004 0.294 0
          rotation 0.7071067811865475 0 -0.7071067811865475 0.2618
          children [
            USE Poste1
          ]
        }
        Transform {
          translation -0.30000000000000004 0.294 0.3
          rotation -0.7071067811865476 0 -0.7071067811865476 0.2618
          children [
            USE Poste1
          ]
        }
        Transform {
          translation 0 0.294 0.30000000000000004
          rotation -0.7071067811865476 0 0.7071067811865476 0.2618
          children [
            USE Poste1
          ]
        }
        Transform {
          translation -0.15000000000000002 0.30000000000000004 0
          rotation 0 0 1 1.5707996938995747
          children [
            Shape {
              appearance USE color_post1
              geometry Cylinder {
                height 0.30000000000000004
                radius 0.019999999999999997
              }
            }
          ]
        }
        Transform {
          translation -0.15000000000000002 0.30000000000000004 0.30000000000000004
          rotation 0 0 1 1.5707996938995747
          children [
            Shape {
              appearance USE color_post1
              geometry Cylinder {
                height 0.30000000000000004
                radius 0.019999999999999997
              }
            }
          ]
        }
        Transform {
          translation -0.005 0.30000000000000004 0.16
          rotation 1 0 0 1.5707996938995747
          children [
            Shape {
              appearance USE color_post1
              geometry Cylinder {
                height 0.30000000000000004
                radius 0.019999999999999997
              }
            }
          ]
        }
        Transform {
          translation -0.3 0.30000000000000004 0.16
          rotation 1 0 0 1.5707996938995747
          children [
            Shape {
              appearance USE color_post1
              geometry Cylinder {
                height 0.30000000000000004
                radius 0.019999999999999997
              }
            }
          ]
        }
        Transform {
          translation -0.15 0.6 0.15
          children [
            Shape {
              appearance USE color_post1
              geometry Box {
                size 0.4 0.019999999999999997 0.4
              }
            }
          ]
        }
      ]
    }
    Group {
      children [
        Transform {
          translation -0.15 0.65 0.15
          children [
            Shape {
              appearance DEF Cilindro_superior PBRAppearance {
                baseColor 0.3333333333333333 0.3411764705882353 0.3254901960784314
                roughness 1
                metalness 0
              }
              geometry Cylinder {
                height 0.1
                radius 0.019999999999999997
              }
            }
            Solid {
              translation 0 0.07 0
              children [
                Shape {
                  geometry Box {
                    size 0.04 0.04 0.09999999999999999
                  }
                }
                Hinge2Joint {
                }
              ]
              name "solid(1)"
            }
          ]
        }
      ]
    }
  ]
}
