#VRML_SIM R2019a utf8
WorldInfo {
}
Viewpoint {
  orientation 0.4874898801503249 0.8547676355586264 0.1781176744529786 5.442355210003927
  position -1.4524304426410564 1.1594044060310034 2.196296986025319
}
TexturedBackground {
}
TexturedBackgroundLight {
}
Floor {
}
Group {
  children [
    Group {
      children [
        Solid {
          translation 0 0.294 0
          rotation 0.7071067811865475 0 0.7071067811865475 0.26180030610042526
          children [
            DEF Poste1 Shape {
              appearance DEF color_post1 PBRAppearance {
                baseColor 0.7568627450980392 0.49019607843137253 0.06666666666666667
                roughness 1
                metalness 0
              }
              geometry Cylinder {
                height 0.6
                radius 0.019999999999999997
              }
            }
          ]
        }
        Transform {
          translation -0.30000000000000004 0.294 0
          rotation 0.7071067811865475 0 -0.7071067811865475 0.2618
          children [
            USE Poste1
          ]
        }
        Transform {
          translation -0.30000000000000004 0.294 0.3
          rotation -0.7071067811865476 0 -0.7071067811865476 0.2618
          children [
            USE Poste1
          ]
        }
        Transform {
          translation 0 0.294 0.30000000000000004
          rotation -0.7071067811865476 0 0.7071067811865476 0.2618
          children [
            USE Poste1
          ]
        }
        Transform {
          translation -0.15000000000000002 0.30000000000000004 0
          rotation 0 0 1 1.5707996938995747
          children [
            Shape {
              appearance USE color_post1
              geometry Cylinder {
                height 0.30000000000000004
                radius 0.019999999999999997
              }
            }
          ]
        }
        Transform {
          translation -0.15000000000000002 0.30000000000000004 0.30000000000000004
          rotation 0 0 1 1.5707996938995747
          children [
            Shape {
              appearance USE color_post1
              geometry Cylinder {
                height 0.30000000000000004
                radius 0.019999999999999997
              }
            }
          ]
        }
        Transform {
          translation -0.005 0.30000000000000004 0.16
          rotation 1 0 0 1.5707996938995747
          children [
            Shape {
              appearance USE color_post1
              geometry Cylinder {
                height 0.30000000000000004
                radius 0.019999999999999997
              }
            }
          ]
        }
        Transform {
          translation -0.3 0.30000000000000004 0.16
          rotation 1 0 0 1.5707996938995747
          children [
            Shape {
              appearance USE color_post1
              geometry Cylinder {
                height 0.30000000000000004
                radius 0.019999999999999997
              }
            }
          ]
        }
        Transform {
          translation -0.15 0.6 0.15
          children [
            Shape {
              appearance USE color_post1
              geometry Box {
                size 0.4 0.019999999999999997 0.4
              }
            }
          ]
        }
      ]
    }
    Group {
      children [
        Transform {
          translation -0.15000000000000002 0.66 0.28
          children [
            Shape {
              appearance DEF Cilindro_superior PBRAppearance {
                baseColor 0.3333333333333333 0.3411764705882353 0.3254901960784314
                roughness 1
                metalness 0
              }
              geometry Cylinder {
                height 0.1
                radius 0.019999999999999997
              }
            }
            Solid {
              translation 0.01299 0.07000000000000461 0.015666799999999998
              rotation 1 0 0 -1.5707996938995747
              children [
                Shape {
                  geometry Cylinder {
                    height 0.1
                    radius 0.03
                  }
                }
                HingeJoint {
                  jointParameters HingeJointParameters {
                    position -0.18493183890124007
                    axis 0 0 1
                    anchor 0 0.03 0.060000000000000005
                    minStop -0.785
                    maxStop 0.785
                  }
                  endPoint Solid {
                    translation 0.027475194779251436 0.17746224490303344 -1.3877787807814457e-17
                    rotation 0.09194311170786129 0.9915104564988912 -0.09194280212630093 1.5793253754273615
                    children [
                      Shape {
                        appearance USE Cilindro_superior
                        geometry Cylinder {
                          height 0.30000000000000004
                          radius 0.01
                        }
                      }
                      Solid {
                        translation 0 0.14 0
                        children [
                          Shape {
                            geometry Box {
                              size 0.03 0.060000000000000005 0.019999999999999997
                            }
                          }
                        ]
                      }
                      Transform {
                        translation 0 -0.25 0
                        rotation 0 0 1 0
                        children [
                          HingeJoint {
                            jointParameters HingeJointParameters {
                            }
                            endPoint Solid {
                              rotation 1 0 0 1.3089969349999997
                              children [
                                Transform {
                                  children [
                                    Solid {
                                      children [
                                        DEF elize Shape {
                                          geometry Cylinder {
                                            height 0.6
                                            radius 0.019999999999999997
                                          }
                                        }
                                      ]
                                    }
                                    Solid {
                                      rotation 0 0 1 1.5707996938995747
                                      children [
                                        USE elize
                                      ]
                                      name "solid(1)"
                                    }
                                  ]
                                }
                              ]
                              name "solid(1)"
                            }
                          }
                        ]
                      }
                    ]
                    physics Physics {
                    }
                  }
                }
              ]
              name "solid(1)"
            }
          ]
        }
      ]
    }
  ]
}
